Workbook

Sheet Summary
A1: Mistri AI | B1: Detailed Project Report — Delhi pilot
A2: First issue, 10 October 2026. Design confirmed with no change. Yellow cells on Inputs and Scope are the inputs.
A4: PROJECT
A5: Name | B5: ='Inputs and Scope'!$B$6
A6: Place | B6: ='Inputs and Scope'!$B$7
A7: Kind | B7: IT system for construction workers, contractors, and vendors
A8: Accounts | B8: ='Inputs and Scope'!$B$8&" workers, "&'Inputs and Scope'!$B$9&" contractors, "&'Inputs and Scope'!$B$10&" vendors"
A9: Length | B9: ='Inputs and Scope'!$B$11&" months, including build and one year of running"
A10: Channels | B10: Android app, WhatsApp, and a website, in Hindi and English
A12: SCOPE IN FIVE LINES
A13: ="1. Delhi pilot for "&'Inputs and Scope'!$B$8&" construction workers, "&'Inputs and Scope'!$B$9&" contractors, and "&'Inputs and Scope'!$B$10&" vendors."
A14: 2. Android app, WhatsApp, and a website, in Hindi and English, on a public cloud in India.
A15: 3. A job in text, audio, or a photo becomes a quantity list and a cost estimate, then a vendor match and a booking.
A16: 4. Site progress, attendance, and photos are recorded, and an internal invoice is marked unpaid or paid.
A17: 5. Sign-in is a phone one-time password. UPI, GST invoicing, and maps are outside this version.
A19: TOTAL COST
A20: Priced subtotal | B20: ='Cost Summary'!$D$11 | D20: Lines that have a sourced rate.
A21: Contingency | B21: ='Cost Summary'!$D$13 | D21: Separate from the line rates.
A22: GST | B22: ='Cost Summary'!$D$14 | D22: Separate from the line rates.
A23: Total | B23: ='Cost Summary'!$D$15 | D23: Priced subtotal plus contingency plus GST.
A24: Still open | B24: ='Cost Summary'!$D$17&" build lines and "&'Cost Summary'!$D$18&" buy lines are marked RATE NEEDED. Their amounts are blank and are not in the total." | D24: Type a rate on Inputs and Scope and the total moves.
A26: TIMELINE
A27: Start | B27: ='Timeline'!$E$5
A28: Finish | B28: ='Timeline'!$B$11
A29: Duration | B29: ='Timeline'!$D$11&" weeks"
A31: KEY RISKS
A32: ='Risks and Compliance'!B5
A33: ='Risks and Compliance'!B6
A34: ='Risks and Compliance'!B7
A36: HOW TO CHANGE A NUMBER
A37: Edit a yellow cell on Inputs and Scope. Rates that are still open are the yellow cells whose value is RATE NEEDED. Replace that word with a number. Do not type over a blue cell. Contingency and GST stay on this cost block and are not inside the unit rates.

Sheet Inputs and Scope
A1: Mistri AI — inputs and scope
A2: Yellow cells with brown type are the only inputs. Change a yellow cell and the sizing, quantities, and totals recalculate. Do not type over a blue figure.
A5: CONFIRMED SCOPE
A6: Project name | B6: Mistri AI | C6: text | D6: Confirmed at intake
A7: Place | B7: Delhi, India | C7: text | D7: Confirmed at intake
A8: Construction workers | B8: 100 | C8: accounts | D8: Pilot cap, confirmed
A9: Contractors | B9: 20 | C9: accounts | D9: Pilot cap, confirmed
A10: Vendors | B10: 20 | C10: accounts | D10: Pilot cap, confirmed
A11: Pilot length | B11: 12 | C11: months | D11: Design, build, and one year of running, confirmed
A12: Languages | B12: 2 | C12: languages | D12: Hindi and English, confirmed
A13: Channels | B13: 3 | C13: channels | D13: Android, WhatsApp, and website, confirmed
A15: VOLUME ASSUMPTIONS
A16: Jobs per contractor per month | B16: 4 | C16: jobs | D16: Assumption 1. A job is counted once.
A17: Description photos per job | B17: 2 | C17: photos | D17: Assumption 2
A18: Audio clips per job | B18: 1 | C18: clips | D18: Assumption 2
A19: Minutes per audio clip | B19: 1 | C19: minutes | D19: Assumption 2. Used only to describe the clip.
A20: Average photo size | B20: 2 | C20: MB | D20: Assumption 9
A21: Average audio size | B21: 1 | C21: MB | D21: Assumption 9
A22: Site updates per job | B22: 12 | C22: updates | D22: Assumption 3
A23: Photos per site update | B23: 1 | C23: photos | D23: Assumption 3
A24: Bookings per job | B24: 2 | C24: bookings | D24: Assumption 4
A25: Catalogue edits per vendor per month | B25: 2 | C25: edits | D25: Assumption 5
A26: Sign-ins per account per month | B26: 8 | C26: sign-ins | D26: Assumption 6. One SMS each.
A27: Share of jobs handled on WhatsApp | B27: 0.5 | C27: share | D27: Assumption 7
... A30: Views of each media file during the year | B30: 3 | C30: views | D30: Assumption 11
A32: PLATFORM ASSUMPTIONS
A33: Peak concurrent share of accounts | B33: 0.2 | C33: share | D33: Assumption 12. Does not reduce the server count.
A34: Database kilobytes per row | B34: 5 | C34: KB | D34: Assumption 13. Metadata only. Photos sit in object storage.
A35: Minimum database volume | B35: 20 | C35: GB | D35: Assumption 13. AWS RDS general-purpose minimum is 20 GiB.
A36: App servers running all month | B36: 2 | C36: servers | D36: Assumption 12. 2 vCPU and 4 GB each, so one can fail.
A37: Hours in a billed month | B37: 730 | C37: hours | D37: Assumption 21. AWS monthly price ÷ hourly price.
A38: Disk per app server | B38: 30 | C38: GB | D38: Assumption 14
A39: Free WhatsApp service messages per month | B39: 1000 | C39: messages | D39: Assumption 15. Set to 0 if messages are billed as utility templates.
A40: Free data transfer out per month | B40: 100 | C40: GB | D40: AWS free allowance, named on the BOM source.
A41: Pilot support days per month | B41: 2 | C41: person-days | D41: Assumption 17
A43: BUILD EFFORT (PLANNING DAYS)
A44: Days — MOD-AUTH phone OTP sign-in | B44: 8 | C44: person-days | D44: Assumption 16
A45: Days — MOD-PROF role and profile | B45: 5 | C45: person-days | D45: Assumption 16
A46: Days — MOD-HOME home and my jobs | B46: 5 | C46: person-days | D46: Assumption 16
A47: Days — MOD-JOB intake of text, audio, and photo | B47: 12 | C47: person-days | D47: Assumption 16
...

Sheet Assumptions
A1: Mistri AI — assumptions
A2: Each assumption names the input it drives. Change the input, not this text, when you want the numbers to move.
A4: No. | B4: Assumption | C4: Effect on quantity or cost | D4: Input
A5: 1 | B5: A job is counted once. Volume is the jobs-per-contractor input. A job a worker creates is inside that count. | C5: ="Jobs per month = "&TEXT('Sizing'!$D$9,"#,##0")&", and "&TEXT('Sizing'!$D$10,"#,##0")&" in the pilot." | D5: Jobs per contractor per month
A6: 2 | B6: Each job has one text description, the stated number of audio clips, and the stated number of description photos. | C6: ="Description media per job = "&TEXT('Sizing'!$D$21,"0.0")&" MB." | D6: Photos, audio clips, minutes
A7: 3 | B7: Each job has the stated number of site updates, and each update has the stated number of photos plus attendance. | C7: ="Site updates = "&TEXT('Sizing'!$D$15,"#,##0")&". Site media per job = "&TEXT('Sizing'!$D$22,"0.0")&" MB." | D7: Site updates, photos per update
A8: 4 | B8: Each job produces one estimate, one material match, the stated number of bookings, and one invoice. | C8: ="Bookings = "&TEXT('Sizing'!$D$13,"#,##0")&". Invoices = "&TEXT('Sizing'!$D$14,"#,##0")&"." | D8: Bookings per job
A9: 5 | B9: Vendors type every catalogue edit. There is no file to load on day one. | C9: ="Catalogue edits = "&TEXT('Sizing'!$D$16,"#,##0")&"." | D9: Catalogue edits per vendor
A10: 6 | B10: Each account signs in at the stated monthly rate. Each sign-in sends one SMS. WhatsApp does not send a second code. | C10: ="OTP SMS = "&TEXT('Sizing'!$D$18,"#,##0")&"." | D10: Sign-ins per account
A11: 7 | B11: The stated share of jobs runs on WhatsApp. Each of those jobs causes the stated number of business messages: estimate, match, booking, one reply per site update, and invoice. | C11: Sets the job part of the WhatsApp message count. | D11: WhatsApp job share and messages per job
A12: 8 | B12: The stated share of catalogue edits is confirmed with one WhatsApp message. | C12: ="WhatsApp business messages per month = "&TEXT('Sizing'!$D$63,"#,##0.0")&"." | D12: Vendor WhatsApp share
A13: 9 | B13: Photos and audio use the stated average sizes. Text is inside the database row, not in object storage. | C13: ="Media per job = "&TEXT('Sizing'!$D$20,"0.0")&" MB." | D13: Photo size, audio size
A14: 10 | B14: Media is kept for the whole pilot. Object storage is billed on the growing total, not on the last month alone. | C14: ="Object storage = "&TEXT('Sizing'!$D$25,"#,##0.00")&" GB-months." | D14: Pilot length
A15: 11 | B15: Each media file is viewed the stated number of times in the year. Uploads are free of transfer-out charges. | C15: ="Downloaded = "&TEXT('Sizing'!$D$53,"#,##0.00")&" GB. Billable transfer = "&TEXT('Sizing'!$D$56,"#,##0.00")&" GB." | D15: Views per file
A16: 12 | B16: Peak concurrency is the stated share of accounts. Two app servers still run all month so one can fail. Concurrency does not reduce the hours. | C16: ="Peak users = "&TEXT('Sizing'!$D$7,"0.0")&". App-server hours = "&TEXT('Sizing'!$D$58,"#,##0")&"." | D16: Concurrent share, app servers
A17: 13 | B17: Each database row is the stated size. The volume billed is the greater of that size and 20 GB, which is the smallest general-purpose RDS volume. | C17: ="Calculated "&TEXT('Sizing'!$D$37,"0.000")&" GB. Provisioned "&TEXT('Sizing'!$D$38,"0")&" GB." | D17: Kilobytes per row, minimum volume
A18: 14 | B18: Each app server has the stated disk. The GB-months are derived. The rupee rate is open. | C18: ="Disk = "&TEXT('Sizing'!$D$60,"#,##0")&" GB-months, rate still RATE NEEDED." | D18: Disk per app server
A19: 15 | B19: WhatsApp messages are treated as service messages, and the published free monthly allowance is subtracted. Set that input to 0 if they are utility templates. | C19: ="Billable WhatsApp messages = "&TEXT('Sizing'!$D$65,"#,##0")&"." | D19: Free WhatsApp messages
A20: 16 | B20: Build person-days are planning allowances, one per design item. They are not a measured take-off. | C20: ="Build days, excluding support = "&TEXT('Sizing'!$D$98,"#,##0")&". Amount stays blank until a day rate is typed." | D20: Days block
A21: 17 | B21: After go-live the pilot is supported for the stated days each month. | C21: ="Support days = "&TEXT('Sizing'!$D$66,"#,##0")&"." | D21: Support days per month
A22: 18 | B22: Contingency is the stated percent of the priced subtotal only. Open lines join it automatically once a rate is typed. | C22: ="Contingency = "&TEXT('Cost Summary'!$D$13,"₹#,##0.00")&"." | D22: Contingency
A23: 19 | B23: GST is the stated percent of priced subtotal plus contingency, on its own line. A tax adviser confirms which purchases are taxable. | C23: ="GST = "&TEXT('Cost Summary'!$D$14,"₹#,##0.00")&"." | D23: GST
A24: 20 | B24: US dollar prices convert at the FBIL reference rate on the inputs sheet. | C24: ="Rate = "&TEXT('Inputs and Scope'!$B$77,"0.0000")&" rupees per dollar." | D24: Rupees per US dollar
A25: 21 | B25: A billed month is 730 hours, which is the divisor AWS uses to show a monthly price from an hourly price. | C25: App-server hours and database hours use this figure. | D25: Hours in a billed month
A26: 22 | B26: One load balancer is allowed for the two servers. Its rate is open. | C26: ="Load-balancer months = "&TEXT('Sizing'!$D$61,"0")&"." | D26: Load balancer rate
A27: 23 | B27: A separate estimate model, if bought, is one fee per job. It stays open so it is not double-counted with the app servers. | C27: ="Model units = "&TEXT('Sizing'!$D$10,"#,##0")&" jobs." | D27: Model fee per job
A28: 24 | B28: The timeline weeks are planning allowances. They move the dates and do not by themselves move the cost. | C28: ="Plan length = "&TEXT('Timeline'!$D$11,"0")&" weeks." | D28: Week inputs

Sheet Design
A1: Mistri AI — design
A2: Trace key = Yes means a BOQ or BOM line must cite this ID. Screens cite the parent module and are not priced a second time.
A4: COMPONENTS — TRACE KEYS
A5: ID | B5: Kind | C5: Name | D5: Trace key | E5: Role in the pilot
A6: USR-W | B6: User | C6: Construction worker | D6: Yes | E6: Creates jobs, books, views own site updates and invoices
A7: USR-C | B7: User | C7: Contractor | D7: Yes | E7: Worker actions, plus site updates and marking invoices paid
A8: USR-V | B8: User | C8: Vendor | D8: Yes | E8: Catalogue, and invoices that name the vendor
A9: CH-AND | B9: Channel | C9: Android app | D9: Yes | E9: Hindi and English screens
A10: CH-WA | B10: Channel | C10: WhatsApp | D10: Yes | E10: The same tasks as a conversation
A11: CH-WEB | B11: Channel | C11: Website | D11: Yes | E11: The Android screens in a browser
A12: PLT-CLOUD | B12: Platform | C12: Public cloud in India | D12: Yes | E12: Hosts the application and the data for one year
A13: PLT-LANG | B13: Platform | C13: Hindi and English | D13: Yes | E13: Both languages on every channel
A14: EXT-OTP | B14: External | C14: SMS one-time-password gateway | D14: Yes | E14: Sends the code for sign-in
A15: EXT-WABA | B15: External | C15: WhatsApp Business API | D15: Yes | E15: Carries the WhatsApp channel
A16: MOD-AUTH | B16: Module | C16: Phone OTP sign-in | D16: Yes | E16: Phone number and one-time password
... A35: JOB-FIT | B35: Job type | C35: Interior fit-out | D35: Yes | E35: Quantity rules inside the estimate
A37: SCREENS — EACH CITES ITS PARENT, WHICH IS THE TRACE KEY
A38: ID | B38: Screen | C38: Parent | D38: Channel | E38: Who uses it
A39: SCR-01 | B39: Enter phone number | C39: MOD-AUTH | D39: Android, website | E39: All roles
A40: SCR-02 | B40: Enter one-time password | C40: MOD-AUTH | D40: Android, website | E40: All roles
A41: SCR-03 | B41: Role and profile | C41: MOD-PROF | D41: Android, website | E41: All roles
A42: SCR-04 | B42: Home | C42: MOD-HOME | D42: Android, website | E42: All roles
A43: SCR-05 | B43: My jobs | C43: MOD-HOME | D43: Android, website | E43: Worker, contractor
A44: SCR-06 | B44: New job | C44: MOD-JOB | D44: Android, website | E44: Worker, contractor
A45: SCR-07 | B45: Estimate and quantities | C45: MOD-EST | D45: Android, website | E45: Worker, contractor
A46: SCR-08 | B46: Vendor catalogue | C46: MOD-CAT | D46: Android, website | E46: Vendor
A47: SCR-09 | B47: Material match | C47: MOD-MATCH | D47: Android, website | E47: Worker, contractor
A48: SCR-10 | B48: Find people by trade | C48: MOD-BOOK | D48: Android, website | E48: Worker, contractor
A49: SCR-11 | B49: Booking | C49: MOD-BOOK | D49: Android, website | E49: Worker and contractor named on it
... A58: SCR-W7 | B58: Invoice status | C58: MOD-INV | D58: WhatsApp | E58: Each role sees their own
A61: SYSTEM CONTEXT
A62: The diagram uses the same IDs as the table above.

Sheet Sizing
A1: Mistri AI — sizing and quantities
A2: Column D is a formula. Column C is the working in words. Yellow inputs live on Inputs and Scope.
A4: USERS
A5: Key | B5: Measure | C5: Working | D5: Quantity | E5: Unit | F5: Design ID
A6: S-ACC | B6: Registered accounts | C6: Workers + contractors + vendors. | D6: ='Inputs and Scope'!$B$8+'Inputs and Scope'!$B$9+'Inputs and Scope'!$B$10 | E6: accounts | F6: USR-W
A7: S-PEAK | B7: Peak concurrent users | C7: Accounts × the peak share. This records load. Server count stays at the input. | D7: ='Sizing'!$D$6*'Inputs and Scope'!$B$33 | E7: users | F7: PLT-CLOUD
A8: JOBS AND RECORDS
A9: S-JOB-M | B9: Jobs per month | C9: Contractors × jobs per contractor. A worker-created job is inside this count so it is not added again. | D9: ='Inputs and Scope'!$B$9*'Inputs and Scope'!$B$16 | E9: jobs | F9: MOD-JOB
A10: S-JOB-Y | B10: Jobs in the pilot | C10: Jobs per month × months. | D10: ='Sizing'!$D$9*'Inputs and Scope'!$B$11 | E10: jobs | F10: MOD-JOB
A11: S-EST | B11: Estimates | C11: One estimate per job. | D11: ='Sizing'!$D$10 | E11: estimates | F11: MOD-EST
A12: S-MATCH | B12: Material matches | C12: One match per job. | D12: ='Sizing'!$D$10 | E12: matches | F12: MOD-MATCH
A13: S-BOOK | B13: Bookings | C13: Jobs × bookings per job. | D13: ='Sizing'!$D$10*'Inputs and Scope'!$B$24 | E13: bookings | F13: MOD-BOOK
A14: S-INV | B14: Invoices | C14: One internal invoice per job. | D14: ='Sizing'!$D$10 | E14: invoices | F14: MOD-INV
A15: S-SITE | B15: Site updates | C15: Jobs × site updates per job. | D15: ='Sizing'!$D$10*'Inputs and Scope'!$B$22 | E15: updates | F15: MOD-SITE
A16: S-CAT | B16: Catalogue edits | C16: Vendors × edits per month × months. | D16: ='Inputs and Scope'!$B$10*'Inputs and Scope'!$B$25*'Inputs and Scope'!$B$11 | E16: edits | F16: MOD-CAT
A17: S-LOGIN | B17: Sign-ins | C17: Accounts × sign-ins per month × months. | D17: ='Sizing'!$D$6*'Inputs and Scope'!$B$26*'Inputs and Scope'!$B$11 | E17: sign-ins | F17: MOD-AUTH
A18: S-SMS | B18: OTP text messages | C18: One SMS per sign-in. WhatsApp does not send a second code. | D18: ='Sizing'!$D$17 | E18: SMS | F18: EXT-OTP
A19: STORAGE
A20: S-MB-JOB | B20: Megabytes of media per job | C20: Description photos and site photos at the average photo size, plus audio clips at the average audio size. | D20: =('Inputs and Scope'!$B$17+'Inputs and Scope'!$B$22*'Inputs and Scope'!$B$23)*'Inputs and Scope'!$B$20+'Inputs and Scope'!$B$18*'Inputs and Scope'!$B$21 | E20: MB | F20: DAT-JOB
A21: S-MB-DESC | B21: Megabytes of description media per job | C21: Description photos and the audio clip only. | D21: ='Inputs and Scope'!$B$17*'Inputs and Scope'!$B$20+'Inputs and Scope'!$B$18*'Inputs and Scope'!$B$21 | E21: MB | F21: DAT-JOB
A22: S-MB-SITE | B22: Megabytes of site media per job | C22: Site photos only. | D22: ='Inputs and Scope'!$B$22*'Inputs and Scope'!$B$23*'Inputs and Scope'!$B$20 | E22: MB | F22: DAT-SITE
A23: S-GB-M | B23: New media per month | C23: Jobs per month × MB per job ÷ 1024. | D23: ='Sizing'!$D$9*'Sizing'!$D$20/1024 | E23: GB | F23: PLT-CLOUD
A24: S-GB-END | B24: Media stored at the end of the pilot | C24: New media each month is kept for the whole pilot, so the last month holds months × the monthly addition. | D24: ='Sizing'!$D$23*'Inputs and Scope'!$B$11 | E24: GB | F24: PLT-CLOUD
A25: S-GBMO | B25: Object storage billed | C25: Month 1 stores one month of media, month 2 stores two, and so on. The sum is monthly new × months × (months + 1) / 2. | D25: ='Sizing'!$D$23*'Inputs and Scope'!$B$11*('Inputs and Scope'!$B$11+1)/2 | E25: GB-months | F25: PLT-CLOUD
A26: S-GBMO-JOB | B26: Object storage for job descriptions | C26: Total object GB-months × the description share of each job's media. | D26: =IF('Sizing'!$D$20=0,0,'Sizing'!$D$25*'Sizing'!$D$21/'Sizing'!$D$20) | E26: GB-months | F26: DAT-JOB
A27: S-GBMO-SITE | B27: Object storage for site photos | C27: Total object GB-months × the site-photo share. The two shares add back to the total. | D27: =IF('Sizing'!$D$20=0,0,'Sizing'!$D$25*'Sizing'!$D$22/'Sizing'!$D$20) | E27: GB-months | F27: DAT-SITE
A28: DATABASE ROWS AND THE PROVISIONED VOLUME
A29: R-ACC | B29: DAT-ACC rows | C29: One standing account row plus one row per sign-in. | D29: ='Sizing'!$D$6+'Sizing'!$D$17 | E29: rows | F29: DAT-ACC
A30: R-JOB | B30: DAT-JOB rows | C30: One metadata row per job. The file itself is in object storage. | D30: ='Sizing'!$D$10 | E30: rows | F30: DAT-JOB
A31: R-EST | B31: DAT-EST rows | C31: One row per estimate. | D31: ='Sizing'!$D$11 | E31: rows | F31: DAT-EST
A32: R-CAT | B32: DAT-CAT rows | C32: One row per catalogue edit. | D32: ='Sizing'!$D$16 | E32: rows | F32: DAT-CAT
A33: R-BOOK | B33: DAT-BOOK rows | C33: One row per booking. | D33: ='Sizing'!$D$13 | E33: rows | F33: DAT-BOOK
A34: R-SITE | B34: DAT-SITE rows | C34: One row per site update. | D34: ='Sizing'!$D$15 | E34: rows | F34: DAT-SITE
A35: R-INV | B35: DAT-INV rows | C35: One row per invoice. | D35: ='Sizing'!$D$14 | E35: rows | F35: DAT-INV
A36: R-ALL | B36: Database rows | C36: Sum of the seven stores. | D36: ='Sizing'!$D$29+'Sizing'!$D$30+'Sizing'!$D$31+'Sizing'!$D$32+'Sizing'!$D$33+'Sizing'!$D$34+'Sizing'!$D$35 | E36: rows | F36: PLT-CLOUD
A37: S-DB-GB | B37: Calculated database size | C37: Rows × kilobytes per row ÷ 1024 ÷ 1024. | D37: ='Sizing'!$D$36*'Inputs and Scope'!$B$34/1024/1024 | E37: GB | F37: PLT-CLOUD
A38: S-DB-PROV | B38: Provisioned database volume | C38: The greater of the calculated size and the 20 GB minimum AWS sells for this volume type. | D38: =MAX('Inputs and Scope'!$B$35,'Sizing'!$D$37) | E38: GB | F38: PLT-CLOUD
A39: GB-DAT-ACC | B39: DAT-ACC share of the database bill | C39: This store's share of rows × the provisioned volume × months. The shares add back to the full volume. | D39: =IF('Sizing'!$D$36=0,0,'Sizing'!$D$29/'Sizing'!$D$36*'Sizing'!$D$38*'Inputs and Scope'!$B$11) | E39: GB-months | F39: DAT-ACC
A40: GB-DAT-JOB | B40: DAT-JOB share of the database bill | C40: This store's share of rows × the provisioned volume × months. The shares add back to the full volume. | D40: =IF('Sizing'!$D$36=0,0,'Sizing'!$D$30/'Sizing'!$D$36*'Sizing'!$D$38*'Inputs and Scope'!$B$11) | E40: GB-months | F40: DAT-JOB
A41: GB-DAT-EST | B41: DAT-EST share of the database bill | C41: This store's share of rows × the provisioned volume × months. The shares add back to the full volume. | D41: =IF('Sizing'!$D$36=0,0,'Sizing'!$D$31/'Sizing'!$D$36*'Sizing'!$D$38*'Inputs and Scope'!$B$11) | E41: GB-months | F41: DAT-EST
...

Sheet BOQ
A1: Mistri AI — bill of quantities
A2: This sheet is the work. The rate of every person-day line reads the single day-rate input. While that input says RATE NEEDED, the amount stays blank.
A4: Line | B4: Phase | C4: Category | D4: Design ID | E4: Description | F4: Quantity | G4: Unit | H4: Rate | I4: Amount (INR) | J4: Source
A5: BQ-01 | B5: Build | C5: Build labour | D5: MOD-AUTH | E5: Build phone OTP sign-in on Android, WhatsApp, and the website | F5: ='Sizing'!$D$68 | G5: person-days | H5: ='Inputs and Scope'!$B$76 | I5: =IF(OR(H5="",H5="RATE NEEDED"),"",F5*H5) | J5: Day rate is the yellow input on Inputs and Scope. No day rate was supplied and no published day rate is used, so the cell stays RATE NEEDED until you type a number.
A6: BQ-02 | B6: Build | C6: Build labour | D6: MOD-PROF | E6: Build role and profile, one role per phone number | F6: ='Sizing'!$D$69 | G6: person-days | H6: ='Inputs and Scope'!$B$76 | I6: =IF(OR(H6="",H6="RATE NEEDED"),"",F6*H6) | J6: Day rate is the yellow input on Inputs and Scope. No day rate was supplied and no published day rate is used, so the cell stays RATE NEEDED until you type a number.
A7: BQ-03 | B7: Build | C7: Build labour | D7: MOD-HOME | E7: Build home and my jobs | F7: ='Sizing'!$D$70 | G7: person-days | H7: ='Inputs and Scope'!$B$76 | I7: =IF(OR(H7="",H7="RATE NEEDED"),"",F7*H7) | J7: Day rate is the yellow input on Inputs and Scope. No day rate was supplied and no published day rate is used, so the cell stays RATE NEEDED until you type a number.
A8: BQ-04 | B8: Build | C8: Build labour | D8: MOD-JOB | E8: Build job intake for text, audio, and photo | F8: ='Sizing'!$D$71 | G8: person-days | H8: ='Inputs and Scope'!$B$76 | I8: =IF(OR(H8="",H8="RATE NEEDED"),"",F8*H8) | J8: Day rate is the yellow input on Inputs and Scope. No day rate was supplied and no published day rate is used, so the cell stays RATE NEEDED until you type a number.
A9: BQ-05 | B9: Build | C9: Build labour | D9: MOD-EST | E9: Build the estimate engine that turns a job into quantities and a cost | F9: ='Sizing'!$D$72 | G9: person-days | H9: ='Inputs and Scope'!$B$76 | I9: =IF(OR(H9="",H9="RATE NEEDED"),"",F9*H9) | J9: Day rate is the yellow input on Inputs and Scope. No day rate was supplied and no published day rate is used, so the cell stays RATE NEEDED until you type a number.
A10: BQ-06 | B10: Build | C10: Build labour | D10: JOB-NEW | E10: Write quantity rules for a new building | F10: ='Sizing'!$D$73 | G10: person-days | H10: ='Inputs and Scope'!$B$76 | I10: =IF(OR(H10="",H10="RATE NEEDED"),"",F10*H10) | J10: Day rate is the yellow input on Inputs and Scope. No day rate was supplied and no published day rate is used, so the cell stays RATE NEEDED until you type a number.
A11: BQ-07 | B11: Build | C11: Build labour | D11: JOB-EXT | E11: Write quantity rules for an extension or extra floor | F11: ='Sizing'!$D$74 | G11: person-days | H11: ='Inputs and Scope'!$B$76 | I11: =IF(OR(H11="",H11="RATE NEEDED"),"",F11*H11) | J11: Day rate is the yellow input on Inputs and Scope. No day rate was supplied and no published day rate is used, so the cell stays RATE NEEDED until you type a number.
A12: BQ-08 | B12: Build | C12: Build labour | D12: JOB-FIT | E12: Write quantity rules for an interior fit-out | F12: ='Sizing'!$D$75 | G12: person-days | H12: ='Inputs and Scope'!$B$76 | I12: =IF(OR(H12="",H12="RATE NEEDED"),"",F12*H12) | J12: Day rate is the yellow input on Inputs and Scope. No day rate was supplied and no published day rate is used, so the cell stays RATE NEEDED until you type a number.
A13: BQ-09 | B13: Build | C13: Build labour | D13: MOD-CAT | E13: Build the vendor catalogue | F13: ='Sizing'!$D$76 | G13: person-days | H13: ='Inputs and Scope'!$B$76 | I13: =IF(OR(H13="",H13="RATE NEEDED"),"",F13*H13) | J13: Day rate is the yellow input on Inputs and Scope. No day rate was supplied and no published day rate is used, so the cell stays RATE NEEDED until you type a number.
A14: BQ-10 | B14: Build | C14: Build labour | D14: MOD-MATCH | E14: Build the locality match | F14: ='Sizing'!$D$77 | G14: person-days | H14: ='Inputs and Scope'!$B$76 | I14: =IF(OR(H14="",H14="RATE NEEDED"),"",F14*H14) | J14: Day rate is the yellow input on Inputs and Scope. No day rate was supplied and no published day rate is used, so the cell stays RATE NEEDED until you type a number.
A15: BQ-11 | B15: Build | C15: Build labour | D15: MOD-BOOK | E15: Build find and book by trade | F15: ='Sizing'!$D$78 | G15: person-days | H15: ='Inputs and Scope'!$B$76 | I15: =IF(OR(H15="",H15="RATE NEEDED"),"",F15*H15) | J15: Day rate is the yellow input on Inputs and Scope. No day rate was supplied and no published day rate is used, so the cell stays RATE NEEDED until you type a number.
A16: BQ-12 | B16: Build | C16: Build labour | D16: MOD-SITE | E16: Build site progress, attendance, photos, and saved location | F16: ='Sizing'!$D$79 | G16: person-days | H16: ='Inputs and Scope'!$B$76 | I16: =IF(OR(H16="",H16="RATE NEEDED"),"",F16*H16) | J16: Day rate is the yellow input on Inputs and Scope. No day rate was supplied and no published day rate is used, so the cell stays RATE NEEDED until you type a number.
A17: BQ-13 | B17: Build | C17: Build labour | D17: MOD-INV | E17: Build the internal invoice and the paid or unpaid mark | F17: ='Sizing'!$D$80 | G17: person-days | H17: ='Inputs and Scope'!$B$76 | I17: =IF(OR(H17="",H17="RATE NEEDED"),"",F17*H17) | J17: Day rate is the yellow input on Inputs and Scope. No day rate was supplied and no published day rate is used, so the cell stays RATE NEEDED until you type a number.
A18: BQ-14 | B18: Build | C18: Build labour | D18: CH-AND | E18: Build the Android app shell | F18: ='Sizing'!$D$81 | G18: person-days | H18: ='Inputs and Scope'!$B$76 | I18: =IF(OR(H18="",H18="RATE NEEDED"),"",F18*H18) | J18: Day rate is the yellow input on Inputs and Scope. No day rate was supplied and no published day rate is used, so the cell stays RATE NEEDED until you type a number.
A19: BQ-15 | B19: Build | C19: Build labour | D19: CH-WEB | E19: Build the website | F19: ='Sizing'!$D$82 | G19: person-days | H19: ='Inputs and Scope'!$B$76 | I19: =IF(OR(H19="",H19="RATE NEEDED"),"",F19*H19) | J19: Day rate is the yellow input on Inputs and Scope. No day rate was supplied and no published day rate is used, so the cell stays RATE NEEDED until you type a number.
A20: BQ-16 | B20: Build | C20: Build labour | D20: CH-WA | E20: Build the WhatsApp conversation | F20: ='Sizing'!$D$83 | G20: person-days | H20: ='Inputs and Scope'!$B$76 | I20: =IF(OR(H20="",H20="RATE NEEDED"),"",F20*H20) | J20: Day rate is the yellow input on Inputs and Scope. No day rate was supplied and no published day rate is used, so the cell stays RATE NEEDED until you type a number.
A21: BQ-17 | B21: Build | C21: Build labour | D21: PLT-LANG | E21: Build Hindi and English across every channel | F21: ='Sizing'!$D$84 | G21: person-days | H21: ='Inputs and Scope'!$B$76 | I21: =IF(OR(H21="",H21="RATE NEEDED"),"",F21*H21) | J21: Day rate is the yellow input on Inputs and Scope. No day rate was supplied and no published day rate is used, so the cell stays RATE NEEDED until you type a number.
A22: BQ-18 | B22: Build | C22: Build labour | D22: PLT-CLOUD | E22: Set up the India-region cloud environment | F22: ='Sizing'!$D$85 | G22: person-days | H22: ='Inputs and Scope'!$B$76 | I22: =IF(OR(H22="",H22="RATE NEEDED"),"",F22*H22) | J22: Day rate is the yellow input on Inputs and Scope. No day rate was supplied and no published day rate is used, so the cell stays RATE NEEDED until you type a number.
A23: BQ-19 | B23: Build | C23: Build labour | D23: DAT-ACC | E23: Create the account store | F23: ='Sizing'!$D$86 | G23: person-days | H23: ='Inputs and Scope'!$B$76 | I23: =IF(OR(H23="",H23="RATE NEEDED"),"",F23*H23) | J23: Day rate is the yellow input on Inputs and Scope. No day rate was supplied and no published day rate is used, so the cell stays RATE NEEDED until you type a number.
A24: BQ-20 | B24: Build | C24: Build labour | D24: DAT-JOB | E24: Create the job store | F24: ='Sizing'!$D$87 | G24: person-days | H24: ='Inputs and Scope'!$B$76 | I24: =IF(OR(H24="",H24="RATE NEEDED"),"",F24*H24) | J24: Day rate is the yellow input on Inputs and Scope. No day rate was supplied and no published day rate is used, so the cell stays RATE NEEDED until you type a number.
A25: BQ-21 | B25: Build | C25: Build labour | D25: DAT-EST | E25: Create the estimate store | F25: ='Sizing'!$D$88 | G25: person-days | H25: ='Inputs and Scope'!$B$76 | I25: =IF(OR(H25="",H25="RATE NEEDED"),"",F25*H25) | J25: Day rate is the yellow input on Inputs and Scope. No day rate was supplied and no published day rate is used, so the cell stays RATE NEEDED until you type a number.
A26: BQ-22 | B26: Build | C26: Build labour | D26: DAT-CAT | E26: Create the catalogue store | F26: ='Sizing'!$D$89 | G26: person-days | H26: ='Inputs and Scope'!$B$76 | I26: =IF(OR(H26="",H26="RATE NEEDED"),"",F26*H26) | J26: Day rate is the yellow input on Inputs and Scope. No day rate was supplied and no published day rate is used, so the cell stays RATE NEEDED until you type a number.
A27: BQ-23 | B27: Build | C27: Build labour | D27: DAT-BOOK | E27: Create the booking store | F27: ='Sizing'!$D$90 | G27: person-days | H27: ='Inputs and Scope'!$B$76 | I27: =IF(OR(H27="",H27="RATE NEEDED"),"",F27*H27) | J27: Day rate is the yellow input on Inputs and Scope. No day rate was supplied and no published day rate is used, so the cell stays RATE NEEDED until you type a number.
A28: BQ-24 | B28: Build | C28: Build labour | D28: DAT-SITE | E28: Create the site store | F28: ='Sizing'!$D$91 | G28: person-days | H28: ='Inputs and Scope'!$B$76 | I28: =IF(OR(H28="",H28="RATE NEEDED"),"",F28*H28) | J28: Day rate is the yellow input on Inputs and Scope. No day rate was supplied and no published day rate is used, so the cell stays RATE NEEDED until you type a number.
A29: BQ-25 | B29: Build | C29: Build labour | D29: DAT-INV | E29: Create the invoice store | F29: ='Sizing'!$D$92 | G29: person-days | H29: ='Inputs and Scope'!$B$76 | I29: =IF(OR(H29="",H29="RATE NEEDED"),"",F29*H29) | J29: Day rate is the yellow input on Inputs and Scope. No day rate was supplied and no published day rate is used, so the cell stays RATE NEEDED until you type a number.
A30: BQ-26 | B30: Build | C30: Build labour | D30: EXT-OTP | E30: Connect the SMS one-time-password gateway | F30: ='Sizing'!$D$93 | G30: person-days | H30: ='Inputs and Scope'!$B$76 | I30: =IF(OR(H30="",H30="RATE NEEDED"),"",F30*H30) | J30: Day rate is the yellow input on Inputs and Scope. No day rate was supplied and no published day rate is used, so the cell stays RATE NEEDED until you type a number.
A31: BQ-27 | B31: Build | C31: Build labour | D31: EXT-WABA | E31: Connect the WhatsApp Business API | F31: ='Sizing'!$D$94 | G31: person-days | H31: ='Inputs and Scope'!$B$76 | I31: =IF(OR(H31="",H31="RATE NEEDED"),"",F31*H31) | J31: Day rate is the yellow input on Inputs and Scope. No day rate was supplied and no published day rate is used, so the cell stays RATE NEEDED until you type a number.
A32: BQ-28 | B32: Build | C32: Build labour | D32: USR-W | E32: Prepare worker onboarding for the pilot | F32: ='Sizing'!$D$95 | G32: person-days | H32: ='Inputs and Scope'!$B$76 | I32: =IF(OR(H32="",H32="RATE NEEDED"),"",F32*H32) | J32: Day rate is the yellow input on Inputs and Scope. No day rate was supplied and no published day rate is used, so the cell stays RATE NEEDED until you type a number.
A33: BQ-29 | B33: Build | C33: Build labour | D33: USR-C | E33: Prepare contractor onboarding for the pilot | F33: ='Sizing'!$D$96 | G33: person-days | H33: ='Inputs and Scope'!$B$76 | I33: =IF(OR(H33="",H33="RATE NEEDED"),"",F33*H33) | J33: Day rate is the yellow input on Inputs and Scope. No day rate was supplied and no published day rate is used, so the cell stays RATE NEEDED until you type a number.
A34: BQ-30 | B34: Build | C34: Build labour | D34: USR-V | E34: Prepare vendor onboarding for the pilot | F34: ='Sizing'!$D$97 | G34: person-days | H34: ='Inputs and Scope'!$B$76 | I34: =IF(OR(H34="",H34="RATE NEEDED"),"",F34*H34) | J34: Day rate is the yellow input on Inputs and Scope. No day rate was supplied and no published day rate is used, so the cell stays RATE NEEDED until you type a number.
A35: BQ-31 | B35: Run | C35: Build labour | D35: PLT-CLOUD | E35: Support the pilot after go-live | F35: ='Sizing'!$D$66 | G35: person-days | H35: ='Inputs and Scope'!$B$76 | I35: =IF(OR(H35="",H35="RATE NEEDED"),"",F35*H35) | J35: Day rate is the yellow input on Inputs and Scope. No day rate was supplied and no published day rate is used, so the cell stays RATE NEEDED until you type a number.
E36: BOQ total (blank amounts are ignored) | I36: =SUM(I5:I35)

Sheet BOM
A1: Mistri AI — bill of materials
A2: Hardware, software, and services to buy or license. Quantity comes from Sizing. Rate comes from Inputs and Scope. Amount converts USD at the FBIL rate and stays blank when the rate is RATE NEEDED.
A4: Line | B4: Phase | C4: Section | D4: Category | E4: Design ID | F4: Item | G4: Specification | H4: Make or equivalent | I4: Quantity | J4: Unit | K4: Rate | L4: Currency | M4: Amount (INR) | N4: Source
A5: BM-01 | B5: Build | C5: Hardware | D5: Hardware | E5: PLT-CLOUD | F5: Servers and phones | G5: No device is purchased. The pilot runs on the public cloud and on the users' own Android phones. | H5: None | I5: =0 | J5: number | K5: ='Inputs and Scope'!$B$94 | L5: INR | M5: =IF(OR(K5="",K5="RATE NEEDED"),"",IF(L5="USD",I5*K5*'Inputs and Scope'!$B$77,I5*K5)) | N5: Confirmed scope, 10 October 2026.
A6: BM-02 | B6: Build | C6: Software | D6: Certificates and accounts | E6: CH-AND | F6: Android store account | G6: One Play Console developer account, once. | H6: Google Play or equivalent store | I6: =1 | J6: account | K6: ='Inputs and Scope'!$B$91 | L6: USD | M6: =IF(OR(K6="",K6="RATE NEEDED"),"",IF(L6="USD",I6*K6*'Inputs and Scope'!$B$77,I6*K6)) | N6: Google Play Console Help, US$25 one-time fee, retrieved 10 October 2026. https://support.google.com/googleplay/android-developer/answer/6112435
A7: BM-03 | B7: Build | C7: Software | D7: Certificates and accounts | E7: CH-WEB | F7: Domain name | G7: One name for one year, .in or .com. | H7: Any ICANN registrar | I7: =1 | J7: year | K7: ='Inputs and Scope'!$B$95 | L7: INR | M7: =IF(OR(K7="",K7="RATE NEEDED"),"",IF(L7="USD",I7*K7*'Inputs and Scope'!$B$77,I7*K7)) | N7: RATE NEEDED. No registrar was chosen.
A8: BM-04 | B8: Build | C8: Software | D8: Certificates and accounts | E8: PLT-CLOUD | F8: TLS certificate | G8: One certificate for the website, renewed through the pilot. | H8: Let's Encrypt or equivalent | I8: =1 | J8: year | K8: ='Inputs and Scope'!$B$92 | L8: INR | M8: =IF(OR(K8="",K8="RATE NEEDED"),"",IF(L8="USD",I8*K8*'Inputs and Scope'!$B$77,I8*K8)) | N8: Let's Encrypt, no charge, retrieved 10 October 2026. https://letsencrypt.org/
A9: BM-05 | B9: Build | C9: Software | D9: Certificates and accounts | E9: PLT-CLOUD | F9: Database software licence | G9: PostgreSQL for all seven stores. The machine is priced on the database hourly line. | H9: PostgreSQL | I9: =1 | J9: licence | K9: ='Inputs and Scope'!$B$93 | L9: INR | M9: =IF(OR(K9="",K9="RATE NEEDED"),"",IF(L9="USD",I9*K9*'Inputs and Scope'!$B$77,I9*K9)) | N9: PostgreSQL Licence, no fee. https://www.postgresql.org/about/licence/
A10: BM-06 | B10: Run | C10: Services | D10: Cloud | E10: PLT-CLOUD | F10: App servers | G10: Two machines, 2 vCPU and 4 GB memory, Linux, running all month in India, for the pilot length. | H10: Amazon EC2 t3.medium or equivalent | I10: ='Sizing'!$D$58 | J10: hours | K10: ='Inputs and Scope'!$B$82 | L10: USD | M10: =IF(OR(K10="",K10="RATE NEEDED"),"",IF(L10="USD",I10*K10*'Inputs and Scope'!$B$77,I10*K10)) | N10: AWS Price List, EC2 Linux on-demand t3.medium, Asia Pacific (Mumbai), USD 0.0448 per hour, publication 2026-10-09.
A11: BM-07 | B11: Run | C11: Services | D11: Cloud | E11: PLT-CLOUD | F11: Database server | G11: One PostgreSQL instance, 2 vCPU and 2 GB memory, Single-AZ, India region. | H11: Amazon RDS db.t3.small or equivalent | I11: ='Sizing'!$D$59 | J11: hours | K11: ='Inputs and Scope'!$B$83 | L11: USD | M11: =IF(OR(K11="",K11="RATE NEEDED"),"",IF(L11="USD",I11*K11*'Inputs and Scope'!$B$77,I11*K11)) | N11: AWS Price List, RDS PostgreSQL db.t3.small Single-AZ, Asia Pacific (Mumbai), USD 0.053 per hour, publication 2026-10-06.
A12: BM-08 | B12: Run | C12: Services | D12: Cloud | E12: PLT-CLOUD | F12: App-server disk | G12: 30 GB general-purpose disk on each app server, for the pilot length. | H12: Amazon EBS gp3 or equivalent | I12: ='Sizing'!$D$60 | J12: GB-months | K12: ='Inputs and Scope'!$B$96 | L12: USD | M12: =IF(OR(K12="",K12="RATE NEEDED"),"",IF(L12="USD",I12*K12*'Inputs and Scope'!$B$77,I12*K12)) | N12: RATE NEEDED. Enter the current Mumbai gp3 USD rate in the yellow input.
A13: BM-09 | B13: Run | C13: Services | D13: Cloud | E13: PLT-CLOUD | F13: Load balancer | G13: One load balancer in front of the two app servers. | H13: Amazon ALB or equivalent | I13: ='Sizing'!$D$61 | J13: months | K13: ='Inputs and Scope'!$B$97 | L13: USD | M13: =IF(OR(K13="",K13="RATE NEEDED"),"",IF(L13="USD",I13*K13*'Inputs and Scope'!$B$77,I13*K13)) | N13: RATE NEEDED. Enter the current Mumbai monthly USD rate, or set the sizing quantity aside if you will not use one.
A14: BM-10 | B14: Run | C14: Services | D14: Cloud | E14: PLT-CLOUD | F14: Database backup | G14: Backup held equal to the provisioned database for each month. | H14: Amazon RDS backup or equivalent | I14: ='Sizing'!$D$62 | J14: GB-months | K14: ='Inputs and Scope'!$B$98 | L14: USD | M14: =IF(OR(K14="",K14="RATE NEEDED"),"",IF(L14="USD",I14*K14*'Inputs and Scope'!$B$77,I14*K14)) | N14: RATE NEEDED. AWS includes some backup storage. The rate stays open so that allowance is not guessed.
A15: BM-11 | B15: Run | C15: Services | D15: Cloud | E15: PLT-CLOUD | F15: Data transfer out | G15: Downloads of media above the free monthly allowance. Uploads are not charged. | H15: AWS data transfer or equivalent | I15: ='Sizing'!$D$56 | J15: GB | K15: ='Inputs and Scope'!$B$88 | L15: USD | M15: =IF(OR(K15="",K15="RATE NEEDED"),"",IF(L15="USD",I15*K15*'Inputs and Scope'!$B$77,I15*K15)) | N15: Free 100 GB per month stated on https://aws.amazon.com/s3/pricing/ retrieved 10 October 2026. Paid tier USD 0.1093 per GB from National IT Service, AWS S3 India pricing, retrieved the same day.
A16: BM-12 | B16: Run | C16: Services | D16: Cloud | E16: DAT-ACC | F16: Account-store share of database disk | G16: This store's share of the one provisioned database volume. | H16: Amazon RDS gp3 or equivalent | I16: ='Sizing'!$D$39 | J16: GB-months | K16: ='Inputs and Scope'!$B$84 | L16: USD | M16: =IF(OR(K16="",K16="RATE NEEDED"),"",IF(L16="USD",I16*K16*'Inputs and Scope'!$B$77,I16*K16)) | N16: AWS Price List, RDS GP3 Single-AZ, Mumbai, USD 0.131 per GB-month, publication 2026-10-06. Share is a formula so the seven stores add up to the volume.
A17: BM-13 | B17: Run | C17: Services | D17: Cloud | E17: DAT-JOB | F17: Job-store share of database disk | G17: Metadata only. The audio and photos are on the object-storage line. | H17: Amazon RDS gp3 or equivalent | I17: ='Sizing'!$D$40 | J17: GB-months | K17: ='Inputs and Scope'!$B$84 | L17: USD | M17: =IF(OR(K17="",K17="RATE NEEDED"),"",IF(L17="USD",I17*K17*'Inputs and Scope'!$B$77,I17*K17)) | N17: Same RDS GP3 rate, publication 2026-10-06.
A18: BM-14 | B18: Run | C18: Services | D18: Cloud | E18: DAT-EST | F18: Estimate-store share of database disk | G18: This store's share of the one volume. | H18: Amazon RDS gp3 or equivalent | I18: ='Sizing'!$D$41 | J18: GB-months | K18: ='Inputs and Scope'!$B$84 | L18: USD | M18: =IF(OR(K18="",K18="RATE NEEDED"),"",IF(L18="USD",I18*K18*'Inputs and Scope'!$B$77,I18*K18)) | N18: Same RDS GP3 rate, publication 2026-10-06.
A19: BM-15 | B19: Run | C19: Services | D19: Cloud | E19: DAT-CAT | F19: Catalogue-store share of database disk | G19: This store's share of the one volume. | H19: Amazon RDS gp3 or equivalent | I19: ='Sizing'!$D$42 | J19: GB-months | K19: ='Inputs and Scope'!$B$84 | L19: USD | M19: =IF(OR(K19="",K19="RATE NEEDED"),"",IF(L19="USD",I19*K19*'Inputs and Scope'!$B$77,I19*K19)) | N19: Same RDS GP3 rate, publication 2026-10-06.
A20: BM-16 | B20: Run | C20: Services | D20: Cloud | E20: DAT-BOOK | F20: Booking-store share of database disk | G20: This store's share of the one volume. | H20: Amazon RDS gp3 or equivalent | I20: ='Sizing'!$D$43 | J20: GB-months | K20: ='Inputs and Scope'!$B$84 | L20: USD | M20: =IF(OR(K20="",K20="RATE NEEDED"),"",IF(L20="USD",I20*K20*'Inputs and Scope'!$B$77,I20*K20)) | N20: Same RDS GP3 rate, publication 2026-10-06.
A21: BM-17 | B21: Run | C21: Services | D21: Cloud | E21: DAT-SITE | F21: Site-store share of database disk | G21: Metadata for attendance and location. Photos are on the object-storage line. | H21: Amazon RDS gp3 or equivalent | I21: ='Sizing'!$D$44 | J21: GB-months | K21: ='Inputs and Scope'!$B$84 | L21: USD | M21: =IF(OR(K21="",K21="RATE NEEDED"),"",IF(L21="USD",I21*K21*'Inputs and Scope'!$B$77,I21*K21)) | N21: Same RDS GP3 rate, publication 2026-10-06.
A22: BM-18 | B22: Run | C22: Services | D22: Cloud | E22: DAT-INV | F22: Invoice-store share of database disk | G22: This store's share of the one volume. | H22: Amazon RDS gp3 or equivalent | I22: ='Sizing'!$D$45 | J22: GB-months | K22: ='Inputs and Scope'!$B$84 | L22: USD | M22: =IF(OR(K22="",K22="RATE NEEDED"),"",IF(L22="USD",I22*K22*'Inputs and Scope'!$B$77,I22*K22)) | N22: Same RDS GP3 rate, publication 2026-10-06.
A23: BM-19 | B23: Run | C23: Services | D23: Cloud | E23: DAT-JOB | F23: Description media storage | G23: Text stays in the database. Audio and description photos sit here, kept for the whole pilot. | H23: Amazon S3 Standard or equivalent | I23: ='Sizing'!$D$26 | J23: GB-months | K23: ='Inputs and Scope'!$B$85 | L23: USD | M23: =IF(OR(K23="",K23="RATE NEEDED"),"",IF(L23="USD",I23*K23*'Inputs and Scope'!$B$77,I23*K23)) | N23: AWS Price List, S3 Standard first 50 TB, Mumbai, USD 0.025 per GB-month, publication 2026-09-28.
A24: BM-20 | B24: Run | C24: Services | D24: Cloud | E24: DAT-SITE | F24: Site-photo storage | G24: Site photos, kept for the whole pilot. | H24: Amazon S3 Standard or equivalent | I24: ='Sizing'!$D$27 | J24: GB-months | K24: ='Inputs and Scope'!$B$85 | L24: USD | M24: =IF(OR(K24="",K24="RATE NEEDED"),"",IF(L24="USD",I24*K24*'Inputs and Scope'!$B$77,I24*K24)) | N24: Same S3 Standard rate, publication 2026-09-28.
A25: BM-21 | B25: Run | C25: Services | D25: Cloud | E25: DAT-JOB | F25: Description upload requests | G25: One PUT per description file. | H25: Amazon S3 or equivalent | I25: ='Sizing'!$D$49 | J25: requests | K25: ='Inputs and Scope'!$B$86 | L25: USD | M25: =IF(OR(K25="",K25="RATE NEEDED"),"",IF(L25="USD",I25*K25*'Inputs and Scope'!$B$77,I25*K25)) | N25: AWS Price List, S3 PUT, Mumbai, USD 0.000005 per request, publication 2026-09-28.
A26: BM-22 | B26: Run | C26: Services | D26: Cloud | E26: DAT-SITE | F26: Site-photo upload requests | G26: One PUT per site photo. | H26: Amazon S3 or equivalent | I26: ='Sizing'!$D$50 | J26: requests | K26: ='Inputs and Scope'!$B$86 | L26: USD | M26: =IF(OR(K26="",K26="RATE NEEDED"),"",IF(L26="USD",I26*K26*'Inputs and Scope'!$B$77,I26*K26)) | N26: Same S3 PUT rate, publication 2026-09-28.
A27: BM-23 | B27: Run | C27: Services | D27: Cloud | E27: DAT-JOB | F27: Description download requests | G27: One GET per view of a description file. | H27: Amazon S3 or equivalent | I27: ='Sizing'!$D$51 | J27: requests | K27: ='Inputs and Scope'!$B$87 | L27: USD | M27: =IF(OR(K27="",K27="RATE NEEDED"),"",IF(L27="USD",I27*K27*'Inputs and Scope'!$B$77,I27*K27)) | N27: AWS Price List, S3 GET, Mumbai, USD 0.0000004 per request, publication 2026-09-28.
A28: BM-24 | B28: Run | C28: Services | D28: Cloud | E28: DAT-SITE | F28: Site-photo download requests | G28: One GET per view of a site photo. | H28: Amazon S3 or equivalent | I28: ='Sizing'!$D$52 | J28: requests | K28: ='Inputs and Scope'!$B$87 | L28: USD | M28: =IF(OR(K28="",K28="RATE NEEDED"),"",IF(L28="USD",I28*K28*'Inputs and Scope'!$B$77,I28*K28)) | N28: Same S3 GET rate, publication 2026-09-28.
A29: BM-25 | B29: Run | C29: Services | D29: Messaging | E29: EXT-OTP | F29: One-time-password SMS | G29: One transactional SMS per sign-in, India DLT route. | H29: SMSGatewayCenter or equivalent | I29: ='Sizing'!$D$18 | J29: SMS | K29: ='Inputs and Scope'!$B$89 | L29: INR | M29: =IF(OR(K29="",K29="RATE NEEDED"),"",IF(L29="USD",I29*K29*'Inputs and Scope'!$B$77,I29*K29)) | N29: SMSGatewayCenter published transactional slab, 10,000 units, INR 0.17 per SMS, GST extra, retrieved 10 October 2026.
A30: BM-26 | B30: Build | C30: Services | D30: Messaging | E30: EXT-OTP | F30: DLT registration | G30: Principal entity and one sender header, required before OTP SMS will be delivered. | H30: Jio, Airtel, or Vi DLT | I30: =1 | J30: registration | K30: ='Inputs and Scope'!$B$99 | L30: INR | M30: =IF(OR(K30="",K30="RATE NEEDED"),"",IF(L30="USD",I30*K30*'Inputs and Scope'!$B$77,I30*K30)) | N30: RATE NEEDED. Published 2026 operator fees disagree on whether GST is inside the figure.
A31: BM-27 | B31: Run | C31: Services | D31: Messaging | E31: EXT-WABA | F31: WhatsApp business messages | G31: Billable service messages after the free monthly allowance. Taxes extra. | H31: Meta WhatsApp Business Platform | I31: ='Sizing'!$D$65 | J31: messages | K31: ='Inputs and Scope'!$B$90 | L31: INR | M31: =IF(OR(K31="",K31="RATE NEEDED"),"",IF(L31="USD",I31*K31*'Inputs and Scope'!$B$77,I31*K31)) | N31: Meta India utility and service rate INR 0.1150 effective 1 October 2026, taxes extra. Free allowance 1,000 service messages per phone number per month. Retrieved 10 October 2026.
A32: BM-28 | B32: Run | C32: Services | D32: Model | E32: MOD-EST | F32: Estimate model | G32: One generation per job from text, audio, or a photo, processed in India. Leave RATE NEEDED if this stays on the app servers. | H32: Any India-region model | I32: ='Sizing'!$D$10 | J32: jobs | K32: ='Inputs and Scope'!$B$100 | L32: INR | M32: =IF(OR(K32="",K32="RATE NEEDED"),"",IF(L32="USD",I32*K32*'Inputs and Scope'!$B$77,I32*K32)) | N32: RATE NEEDED. No India-region model price was selected.
F33: BOM total (blank amounts are ignored) | M33: =SUM(M5:M32)

Sheet Timeline
A1: Mistri AI — timeline
A2: Durations are the yellow week inputs. Dates are formulas from the start date. They are a plan, not a promise.
A4: Phase | B4: Milestone | C4: Depends on | D4: Duration (weeks) | E4: Start | F4: Finish | G4: Design IDs
A5: Design | B5: Design confirmed. Confirmed scope and this design | C5: None | D5: =0 | E5: ='Inputs and Scope'!$B$103 | F5: =E5+D5*7 | G5: All trace keys
A6: Build | B6: Build and integrate. Android, WhatsApp, website, and cloud environment ready | C6: Design | D6: ='Inputs and Scope'!$B$104 | E6: =F5 | F6: =E6+D6*7 | G6: Modules, channels, stores, EXT-OTP, EXT-WABA
A7: Onboarding | B7: Pilot onboarding. Workers, contractors, and vendors can sign in | C7: Build | D7: ='Inputs and Scope'!$B$105 | E7: =F6 | F7: =E7+D7*7 | G7: USR-W, USR-C, USR-V
A8: Run | B8: Pilot operation. One year of use inside the pilot caps | C8: Onboarding | D8: ='Inputs and Scope'!$B$106 | E8: =F7 | F8: =E8+D8*7 | G8: PLT-CLOUD
A9: Close-out | B9: Pilot review. Quantities and open rates reviewed against actual use | C9: Run | D9: ='Inputs and Scope'!$B$107 | E9: =F8 | F9: =E9+D9*7 | G9: PLT-CLOUD
A11: Pilot finish | B11: =F9 | C11: Weeks from start | D11: =SUM(D5:D9)

Sheet Cost Summary
A1: Mistri AI — cost summary
A2: Contingency and GST are separate from the line rates. Lines marked RATE NEEDED are counted and are not in the rupee total.
A4: Category | B4: Build (INR) | C4: Run (INR) | D4: Total (INR) | E4: What is included
A5: Build labour | B5: =IF(COUNTIFS('BOQ'!$B$5:$B$35,"Build",'BOQ'!$C$5:$C$35,A5,'BOQ'!$H$5:$H$35,">=0")=0,"",SUMIFS('BOQ'!$I$5:$I$35,'BOQ'!$B$5:$B$35,"Build",'BOQ'!$C$5:$C$35,A5)) | C5: =IF(COUNTIFS('BOQ'!$B$5:$B$35,"Run",'BOQ'!$C$5:$C$35,A5,'BOQ'!$H$5:$H$35,">=0")=0,"",SUMIFS('BOQ'!$I$5:$I$35,'BOQ'!$B$5:$B$35,"Run",'BOQ'!$C$5:$C$35,A5)) | D5: =IF(AND(B5="",C5=""),"",N(B5)+N(C5)) | E5: Person-days. Blank until the day rate is typed.
A6: Cloud | B6: =IF(COUNTIFS('BOM'!$B$5:$B$32,"Build",'BOM'!$D$5:$D$32,A6,'BOM'!$K$5:$K$32,">=0")=0,"",SUMIFS('BOM'!$M$5:$M$32,'BOM'!$B$5:$B$32,"Build",'BOM'!$D$5:$D$32,A6)) | C6: =IF(COUNTIFS('BOM'!$B$5:$B$32,"Run",'BOM'!$D$5:$D$32,A6,'BOM'!$K$5:$K$32,">=0")=0,"",SUMIFS('BOM'!$M$5:$M$32,'BOM'!$B$5:$B$32,"Run",'BOM'!$D$5:$D$32,A6)) | D6: =IF(AND(B6="",C6=""),"",N(B6)+N(C6)) | E6: From the BOM. A blank category still has lines marked RATE NEEDED.
A7: Messaging | B7: =IF(COUNTIFS('BOM'!$B$5:$B$32,"Build",'BOM'!$D$5:$D$32,A7,'BOM'!$K$5:$K$32,">=0")=0,"",SUMIFS('BOM'!$M$5:$M$32,'BOM'!$B$5:$B$32,"Build",'BOM'!$D$5:$D$32,A7)) | C7: =IF(COUNTIFS('BOM'!$B$5:$B$32,"Run",'BOM'!$D$5:$D$32,A7,'BOM'!$K$5:$K$32,">=0")=0,"",SUMIFS('BOM'!$M$5:$M$32,'BOM'!$B$5:$B$32,"Run",'BOM'!$D$5:$D$32,A7)) | D7: =IF(AND(B7="",C7=""),"",N(B7)+N(C7)) | E7: From the BOM. A blank category still has lines marked RATE NEEDED.
A8: Certificates and accounts | B8: =IF(COUNTIFS('BOM'!$B$5:$B$32,"Build",'BOM'!$D$5:$D$32,A8,'BOM'!$K$5:$K$32,">=0")=0,"",SUMIFS('BOM'!$M$5:$M$32,'BOM'!$B$5:$B$32,"Build",'BOM'!$D$5:$D$32,A8)) | C8: =IF(COUNTIFS('BOM'!$B$5:$B$32,"Run",'BOM'!$D$5:$D$32,A8,'BOM'!$K$5:$K$32,">=0")=0,"",SUMIFS('BOM'!$M$5:$M$32,'BOM'!$B$5:$B$32,"Run",'BOM'!$D$5:$D$32,A8)) | D8: =IF(AND(B8="",C8=""),"",N(B8)+N(C8)) | E8: From the BOM. A blank category still has lines marked RATE NEEDED.
A9: Hardware | B9: =IF(COUNTIFS('BOM'!$B$5:$B$32,"Build",'BOM'!$D$5:$D$32,A9,'BOM'!$K$5:$K$32,">=0")=0,"",SUMIFS('BOM'!$M$5:$M$32,'BOM'!$B$5:$B$32,"Build",'BOM'!$D$5:$D$32,A9)) | C9: =IF(COUNTIFS('BOM'!$B$5:$B$32,"Run",'BOM'!$D$5:$D$32,A9,'BOM'!$K$5:$K$32,">=0")=0,"",SUMIFS('BOM'!$M$5:$M$32,'BOM'!$B$5:$B$32,"Run",'BOM'!$D$5:$D$32,A9)) | D9: =IF(AND(B9="",C9=""),"",N(B9)+N(C9)) | E9: From the BOM. A blank category still has lines marked RATE NEEDED.
A10: Model | B10: =IF(COUNTIFS('BOM'!$B$5:$B$32,"Build",'BOM'!$D$5:$D$32,A10,'BOM'!$K$5:$K$32,">=0")=0,"",SUMIFS('BOM'!$M$5:$M$32,'BOM'!$B$5:$B$32,"Build",'BOM'!$D$5:$D$32,A10)) | C10: =IF(COUNTIFS('BOM'!$B$5:$B$32,"Run",'BOM'!$D$5:$D$32,A10,'BOM'!$K$5:$K$32,">=0")=0,"",SUMIFS('BOM'!$M$5:$M$32,'BOM'!$B$5:$B$32,"Run",'BOM'!$D$5:$D$32,A10)) | D10: =IF(AND(B10="",C10=""),"",N(B10)+N(C10)) | E10: From the BOM. A blank category still has lines marked RATE NEEDED.
A11: Priced subtotal | B11: =SUM(B5:B10) | C11: =SUM(C5:C10) | D11: =B11+C11 | E11: Sum of amounts that have a numeric rate.
A13: Contingency | B13: ='Inputs and Scope'!$B$78 | D13: =D11*B13 | E13: Percent of the priced subtotal. It is not hidden inside the line rates.
A14: GST | B14: ='Inputs and Scope'!$B$79 | D14: =(D11+D13)*B14 | E14: Percent of priced subtotal plus contingency. Confirm taxable lines with a tax adviser.
A15: Total with contingency and GST | D15: =D11+D13+D14 | E15: Excludes every line still marked RATE NEEDED.
A17: BOQ lines still RATE NEEDED | D17: =COUNTIF('BOQ'!$H$5:$H$35,"RATE NEEDED")
A18: BOM lines still RATE NEEDED | D18: =COUNTIF('BOM'!$K$5:$K$32,"RATE NEEDED")
A20: RECONCILIATION
A21: BOQ total | D21: ='BOQ'!I36
A22: BOM total | D22: ='BOM'!M33
A23: BOQ plus BOM | D23: =D21+D22
A24: Matches priced subtotal | D24: =IF(ABS(D23-D11)<0.01,"Yes","No")
A26: BY CHANNEL OF BUY
A27: Hardware | D27: =SUMIF('BOM'!$C$5:$C$32,"Hardware",'BOM'!$M$5:$M$32)
A28: Software | D28: =SUMIF('BOM'!$C$5:$C$32,"Software",'BOM'!$M$5:$M$32)
A29: Services | D29: =SUMIF('BOM'!$C$5:$C$32,"Services",'BOM'!$M$5:$M$32)

Sheet Risks and Compliance
A1: Mistri AI — risks and compliance
A2: Effects that can be calculated point at the workbook. The rest are conditions to watch.
A4: ID | B4: Risk | C4: What it does to the pilot | D4: Effect on this report | E4: Level | F4: Design IDs | G4: Response
A5: R1 | B5: Build day rate is open | C5: The person-day quantities are in the BOQ. They have no rupee amount until the day-rate input is filled. That labour is likely to be larger than the cloud bill. | D5: ="BOQ lines still open: "&'Cost Summary'!$D$17&". Priced total today excludes them." | E5: High | F5: All build IDs | G5: Type a day rate on Inputs and Scope. Every labour line then prices itself.
A6: R2 | B6: WhatsApp messages may all be billable | C6: The quantity subtracts 1,000 free service messages a month. If Meta treats these messages as utility templates, that allowance does not apply. | D6: ="Annual messages "&TEXT('Sizing'!$D$63*'Inputs and Scope'!$B$11,"#,##0")&" × "&TEXT('Inputs and Scope'!$B$90,"₹0.0000")&" = "&TEXT('Sizing'!$D$63*'Inputs and Scope'!$B$11*'Inputs and Scope'!$B$90,"₹#,##0.00")&" if the free allowance is set to 0." | E6: Medium | F6: EXT-WABA, CH-WA | G6: Set the free-allowance input to 0 and the BOM recalculates. Keep marketing messages out of the pilot.
A7: R3 | B7: Worker data with OTP only | C7: The pilot stores name, phone, trade, photos, audio, and a saved location. The confirmed security bar is a one-time password, with no audit log and no formal privacy programme. | D7: A complaint or a DPDP notice can stop the pilot. It does not change a quantity until the scope changes. | E7: High | F7: DAT-ACC, DAT-JOB, DAT-SITE, MOD-AUTH | G7: Before go-live, add a short privacy notice and a way to delete an account, as a scope change.
A8: R4 | B8: SMS will not arrive without DLT | C8: India requires a registered principal entity and a template before transactional SMS is delivered. Sign-in depends on that SMS. | D8: The registration line is RATE NEEDED. Login quantity is already counted. | E8: High | F8: EXT-OTP, MOD-AUTH | G8: Start DLT registration during the build phase, not on the week of go-live.
A9: R5 | B9: Estimates use typed vendor prices | C9: There is no starting price list and no map. A match can only use what the vendor typed, including a wrong locality or a stale price. | D9: No cost line changes. Estimate quality is the product risk. | E9: Medium | F9: MOD-CAT, MOD-MATCH, MOD-EST | G9: Show the vendor's typed date on the match screen so the contractor sees how old the price is.
A10: R6 | B10: Single database zone | C10: The database price is a Single-AZ instance. A zone failure takes the pilot offline. | D10: A second zone is a different AWS rate. It is not in this issue. | E10: Medium | F10: PLT-CLOUD, DAT-ACC | G10: Accept the downtime for the pilot, or price a Multi-AZ instance as a change.
A11: R7 | B11: Dollar prices move | C11: Cloud lines are USD rates converted at the FBIL rate of 9 October 2026. | D11: Edit the rupees-per-dollar input. Every USD line recalculates. | E11: Low | F11: PLT-CLOUD | G11: Replace the FX input with the FBIL rate on the day you place the order.
A12: R8 | B12: Model fee is open | C12: Hindi speech and photo estimates may need a paid model. The app servers are already priced. A separate model must not be added twice. | D12: The model line is one per job and stays RATE NEEDED. | E12: Medium | F12: MOD-EST, MOD-JOB | G12: If the model runs on the two app servers, leave the rate as RATE NEEDED.
A15: COMPLIANCE
A16: ID | B16: Rule | C16: How it touches this pilot | D16: Where it sits in the report
A17: C1 | B17: DPDP Act 2023 | C17: Phone numbers, names, photos, audio, and location are personal data. The confirmed pilot does not include a privacy programme. | D17: Treat the risk R3 response as a gate before real workers are invited.
A18: C2 | B18: TRAI commercial-communication rules | C18: OTP SMS needs DLT registration, a header, and a template. | D18: Priced as a RATE NEEDED registration plus the SMS rate.
A19: C3 | B19: Meta WhatsApp Business policy | C19: Business-initiated messages follow Meta's categories and the rate card of 1 October 2026. | D19: The BOM uses the India service and utility rate and the published free allowance.
A20: C4 | B20: GST on this project | C20: The product does not raise GST invoices. The project's own purchases can still attract GST. | D20: GST is a separate line at the input rate, not inside the unit rates.
A21: C5 | B21: Payments | C21: The pilot does not collect money, so it does not need a payment-aggregator licence. | D21: UPI stays out of scope. The invoice is a record of paid or unpaid.
A22: C6 | B22: Maps and location | C22: A location saved with a site update is a record. It is not sent to a map service. | D22: No map licence is in the BOM.

Sheet Change Log
A1: Mistri AI — change log
A2: Corrections after your feedback are added here and applied everywhere they apply.
A4: No. | B4: Date | C4: Where | D4: What changed | E4: Carried into
A5: CL-01 | B5: 46305 | C5: Scope | D5: Scope confirmed with no change. | E5: Inputs and Scope
A6: CL-02 | B6: 46305 | C6: Design | D6: Design confirmed with no change to IDs, screens, or roles. | E6: Design, BOQ, BOM
A7: CL-03 | B7: 46305 | C7: Trace rule | D7: Screen IDs stay under the parent module and are not priced a second time. This was the rule in the confirmed design. | E7: BOQ, BOM
A8: CL-04 | B8: 46305 | C8: Rates | D8: No rate was invented. Published rates are named with their date. Every other rate is the input RATE NEEDED and its amount is blank. | E8: BOQ, BOM, Cost Summary
A9: CL-05 | B9: 46305 | C9: Self-check | D9: Checked before issue: every trace ID has a line, every line cites a trace ID, quantities are formulas from Sizing, totals reconcile, and every numeric rate has a source. | E9: Cost Summary reconciliation
A10: CL-06 | B10: 46305 | C10: Cost Summary | D10: A category with no numeric rate is left blank. It is not shown as zero, so the open day rate and the open model fee are not read as a free item. | E10: Summary total
